2019-03-11 21:35:32,120 ERROR: Exception on /reset_password_request [POST] [in /home/ruanheng/MicroBlog/venv/lib/python3.6/site-packages/flask/app.py:1761]
Traceback (most recent call last):
  File "/home/ruanheng/MicroBlog/venv/lib/python3.6/site-packages/flask/app.py", line 2292, in wsgi_app
    response = self.full_dispatch_request()
  File "/home/ruanheng/MicroBlog/venv/lib/python3.6/site-packages/flask/app.py", line 1815, in full_dispatch_request
    rv = self.handle_user_exception(e)
  File "/home/ruanheng/MicroBlog/venv/lib/python3.6/site-packages/flask/app.py", line 1718, in handle_user_exception
    reraise(exc_type, exc_value, tb)
  File "/home/ruanheng/MicroBlog/venv/lib/python3.6/site-packages/flask/_compat.py", line 35, in reraise
    raise value
  File "/home/ruanheng/MicroBlog/venv/lib/python3.6/site-packages/flask/app.py", line 1813, in full_dispatch_request
    rv = self.dispatch_request()
  File "/home/ruanheng/MicroBlog/venv/lib/python3.6/site-packages/flask/app.py", line 1799, in dispatch_request
    return self.view_functions[rule.endpoint](**req.view_args)
  File "/home/ruanheng/MicroBlog/app/routes.py", line 239, in reset_password_request
    send_password_reset_email(user)
  File "/home/ruanheng/MicroBlog/app/email.py", line 32, in send_password_reset_email
    user=user, token=token))
  File "/home/ruanheng/MicroBlog/venv/lib/python3.6/site-packages/flask/templating.py", line 135, in render_template
    context, ctx.app)
  File "/home/ruanheng/MicroBlog/venv/lib/python3.6/site-packages/flask/templating.py", line 117, in _render
    rv = template.render(context)
  File "/home/ruanheng/MicroBlog/venv/lib/python3.6/site-packages/jinja2/asyncsupport.py", line 76, in render
    return original_render(self, *args, **kwargs)
  File "/home/ruanheng/MicroBlog/venv/lib/python3.6/site-packages/jinja2/environment.py", line 1008, in render
    return self.environment.handle_exception(exc_info, True)
  File "/home/ruanheng/MicroBlog/venv/lib/python3.6/site-packages/jinja2/environment.py", line 780, in handle_exception
    reraise(exc_type, exc_value, tb)
  File "/home/ruanheng/MicroBlog/venv/lib/python3.6/site-packages/jinja2/_compat.py", line 37, in reraise
    raise value.with_traceback(tb)
  File "/home/ruanheng/MicroBlog/app/templates/email/reset_password.html", line 11, in top-level template code
    <p>{{ url_for('reset_password', token=token, _external=True) }}</p>
  File "/home/ruanheng/MicroBlog/venv/lib/python3.6/site-packages/flask/helpers.py", line 356, in url_for
    return appctx.app.handle_url_build_error(error, endpoint, values)
  File "/home/ruanheng/MicroBlog/venv/lib/python3.6/site-packages/flask/app.py", line 2061, in handle_url_build_error
    reraise(exc_type, exc_value, tb)
  File "/home/ruanheng/MicroBlog/venv/lib/python3.6/site-packages/flask/_compat.py", line 35, in reraise
    raise value
  File "/home/ruanheng/MicroBlog/venv/lib/python3.6/site-packages/flask/helpers.py", line 345, in url_for
    force_external=external)
  File "/home/ruanheng/MicroBlog/venv/lib/python3.6/site-packages/werkzeug/routing.py", line 1776, in build
    raise BuildError(endpoint, values, method, self)
werkzeug.routing.BuildError: Could not build url for endpoint 'reset_password ' with values ['token']. Did you mean 'reset_password' instead?
2019-03-11 21:35:55,873 INFO: Microblog startup [in /home/ruanheng/MicroBlog/app/__init__.py:72]
2019-03-11 21:37:33,931 ERROR: Exception on /reset_password/eyJ0eXAiOiJKV1QiLCJhbGciOiJIUzI1NiJ9.eyJyZXNldF9wYXNzd29yZCI6MywiZXhwIjoxNTUyMzExOTYyLjA5OTA2MDV9.aG6eLlneB_AO_mk-Z84yNqpngPfTqpLe_EJsWanEuYQ [GET] [in /home/ruanheng/MicroBlog/venv/lib/python3.6/site-packages/flask/app.py:1761]
Traceback (most recent call last):
  File "/home/ruanheng/MicroBlog/venv/lib/python3.6/site-packages/flask/app.py", line 2292, in wsgi_app
    response = self.full_dispatch_request()
  File "/home/ruanheng/MicroBlog/venv/lib/python3.6/site-packages/flask/app.py", line 1815, in full_dispatch_request
    rv = self.handle_user_exception(e)
  File "/home/ruanheng/MicroBlog/venv/lib/python3.6/site-packages/flask/app.py", line 1718, in handle_user_exception
    reraise(exc_type, exc_value, tb)
  File "/home/ruanheng/MicroBlog/venv/lib/python3.6/site-packages/flask/_compat.py", line 35, in reraise
    raise value
  File "/home/ruanheng/MicroBlog/venv/lib/python3.6/site-packages/flask/app.py", line 1813, in full_dispatch_request
    rv = self.dispatch_request()
  File "/home/ruanheng/MicroBlog/venv/lib/python3.6/site-packages/flask/app.py", line 1799, in dispatch_request
    return self.view_functions[rule.endpoint](**req.view_args)
  File "/home/ruanheng/MicroBlog/app/routes.py", line 253, in reset_password
    user = User.verify_reset_password_token(token)
  File "/home/ruanheng/MicroBlog/app/models.py", line 131, in verify_reset_password_token
    return User.query.get(id)
  File "/home/ruanheng/MicroBlog/venv/lib/python3.6/site-packages/sqlalchemy/orm/query.py", line 936, in get
    return self._get_impl(ident, loading.load_on_pk_identity)
  File "/home/ruanheng/MicroBlog/venv/lib/python3.6/site-packages/sqlalchemy/orm/query.py", line 1005, in _get_impl
    % ",".join("'%s'" % c for c in mapper.primary_key)
sqlalchemy.exc.InvalidRequestError: Incorrect number of values in identifier to formulate primary key for query.get(); primary key columns are 'user.id'
2019-03-11 21:51:03,367 INFO: Microblog startup [in /home/ruanheng/MicroBlog/app/__init__.py:72]
2019-03-12 06:07:09,920 INFO: Microblog startup [in /home/ruanheng/MicroBlog/app/__init__.py:72]
2019-03-16 22:17:44,352 INFO: Microblog startup                  [in /home/ruanheng/MicroBlog/app/__init__.py:105]
2019-03-16 22:18:30,129 INFO: Microblog startup                  [in /home/ruanheng/MicroBlog/app/__init__.py:105]
2019-03-16 22:31:07,803 INFO: Microblog startup                  [in /home/ruanheng/MicroBlog/app/__init__.py:105]
2019-03-16 22:34:55,631 INFO: Microblog startup                  [in /home/ruanheng/MicroBlog/app/__init__.py:105]
2019-03-16 22:35:34,191 ERROR: Exception on /auth/reset_password_request [POST]                  [in /home/ruanheng/MicroBlog/venv/lib/python3.6/site-packages/flask/app.py:1761]
Traceback (most recent call last):
  File "/home/ruanheng/MicroBlog/venv/lib/python3.6/site-packages/flask/app.py", line 2292, in wsgi_app
    response = self.full_dispatch_request()
  File "/home/ruanheng/MicroBlog/venv/lib/python3.6/site-packages/flask/app.py", line 1815, in full_dispatch_request
    rv = self.handle_user_exception(e)
  File "/home/ruanheng/MicroBlog/venv/lib/python3.6/site-packages/flask/app.py", line 1718, in handle_user_exception
    reraise(exc_type, exc_value, tb)
  File "/home/ruanheng/MicroBlog/venv/lib/python3.6/site-packages/flask/_compat.py", line 35, in reraise
    raise value
  File "/home/ruanheng/MicroBlog/venv/lib/python3.6/site-packages/flask/app.py", line 1813, in full_dispatch_request
    rv = self.dispatch_request()
  File "/home/ruanheng/MicroBlog/venv/lib/python3.6/site-packages/flask/app.py", line 1799, in dispatch_request
    return self.view_functions[rule.endpoint](**req.view_args)
  File "/home/ruanheng/MicroBlog/app/auth/routes.py", line 89, in reset_password_request
    send_password_reset_email(user)
  File "/home/ruanheng/MicroBlog/app/auth/email.py", line 41, in send_password_reset_email
    user=user, token=token),
  File "/home/ruanheng/MicroBlog/venv/lib/python3.6/site-packages/flask/templating.py", line 135, in render_template
    context, ctx.app)
  File "/home/ruanheng/MicroBlog/venv/lib/python3.6/site-packages/flask/templating.py", line 117, in _render
    rv = template.render(context)
  File "/home/ruanheng/MicroBlog/venv/lib/python3.6/site-packages/jinja2/asyncsupport.py", line 76, in render
    return original_render(self, *args, **kwargs)
  File "/home/ruanheng/MicroBlog/venv/lib/python3.6/site-packages/jinja2/environment.py", line 1008, in render
    return self.environment.handle_exception(exc_info, True)
  File "/home/ruanheng/MicroBlog/venv/lib/python3.6/site-packages/jinja2/environment.py", line 780, in handle_exception
    reraise(exc_type, exc_value, tb)
  File "/home/ruanheng/MicroBlog/venv/lib/python3.6/site-packages/jinja2/_compat.py", line 37, in reraise
    raise value.with_traceback(tb)
  File "/home/ruanheng/MicroBlog/app/templates/email/reset_password.txt", line 5, in top-level template code
    {{ url_for('reset_password', token=token, _external=True) }}
  File "/home/ruanheng/MicroBlog/venv/lib/python3.6/site-packages/flask/helpers.py", line 356, in url_for
    return appctx.app.handle_url_build_error(error, endpoint, values)
  File "/home/ruanheng/MicroBlog/venv/lib/python3.6/site-packages/flask/app.py", line 2061, in handle_url_build_error
    reraise(exc_type, exc_value, tb)
  File "/home/ruanheng/MicroBlog/venv/lib/python3.6/site-packages/flask/_compat.py", line 35, in reraise
    raise value
  File "/home/ruanheng/MicroBlog/venv/lib/python3.6/site-packages/flask/helpers.py", line 345, in url_for
    force_external=external)
  File "/home/ruanheng/MicroBlog/venv/lib/python3.6/site-packages/werkzeug/routing.py", line 1776, in build
    raise BuildError(endpoint, values, method, self)
werkzeug.routing.BuildError: Could not build url for endpoint 'reset_password' with values ['token']. Did you mean 'auth.reset_password' instead?
2019-03-16 22:36:08,076 INFO: Microblog startup                  [in /home/ruanheng/MicroBlog/app/__init__.py:105]
